Workbook

Sheet Anford_QZBW_zert_spez
A1: ID | B1: Programm | C1: Akteur | D1: Rolle | E1: Prozesskategorie | F1: Administrative Tätigkeit (Objekt + Verb) | G1: Fachliche Anforderung / erforderlicher Nachweis | H1: Häufigkeit | I1: Fallzahl / Bezugsgröße | J1: Zeitaufwand je Vorgang (Min.) | K1: Gesamter Zeitaufwand (Std.) | L1: Stundensatz (EUR/Std.) | M1: Arbeitszeitkosten (EUR) | N1: Quelldokument | O1: Genaue Fundstelle | P1: Wörtliches Zitat
A2: QZ-0001 | B2: QZBW | C2: Traubenerzeuger / landwirtschaftlicher Betrieb | D2: Traubenerzeuger; Bezugsform: Gruppe | E2: Verträge | F2: Teilnahmevereinbarung mit der Erzeugergruppe prüfen, unterzeichnen und übermitteln | G2: Unterzeichnete Teilnahmevereinbarung zwischen Traubenerzeuger und Erzeugergruppe | H2: einmalig | I2: 1 | J2: 15 | K2: 0.25 | L2: 50 | M2: 12.5 | N2: QZBW – Teilnahmevereinbarung Gruppenzertifizierung (pflanzliche Bereiche), Stand 2023 | O2: S. 1, Ziff. I.1; S. 2, Ziff. I.11 | P2: Der Erzeugerbetrieb erklärt seine Teilnahme am Gruppenzertifizierungssystem des oben genannten gruppenführenden Unternehmens. […] Mit dieser Erklärung treten alle früheren einzelbetrieblichen Teilnahmevereinbarungen des Erzeugers gegenüber einem Lizenznehmer […] außer Kraft.
A3: QZ-0002 | B3: QZBW | C3: Traubenerzeuger / landwirtschaftlicher Betrieb | D3: Traubenerzeuger; Bezugsform: Gruppe | E3: Ausfüllen von Checklisten und Formulare | F3: Eigenkontroll-Checkliste des landwirtschaftlichen Betriebs ausfüllen und ablegen | G3: Vollständig bearbeitete Eigenkontroll-Checkliste des landwirtschaftlichen Betriebs | H3: einmalig | I3: 1 | J3: 30 | K3: 0.5 | L3: 50 | M3: 25 | N3: QZBW – Programmbestimmungen, Stand 01.01.2025 | O3: Programmbestimmungen QZBW 2025, S. 14, Abschnitt 5.5 | P3: Die Eigenkontrolle ist obligatorischer Bestandteil des Qualitätssicherungskonzeptes im „System Qualitätszeichen Baden-Württemberg“. Alle Teilnehmer müssen die Durchführung der Eigenkontrolle dokumentieren und nachweisen.
A4: QZ-0003 | B4: QZBW | C4: Traubenerzeuger / landwirtschaftlicher Betrieb | D4: Traubenerzeuger; Bezugsform: Gruppe | E4: Ausfüllen von Checklisten und Formulare | F4: GVO-Freiheitsbescheinigung ausfüllen beziehungsweise einholen und zusammen mit den zugehörigen Nachweisen ablegen | G4: Vollständiger Nachweis der GVO-Freiheit einschließlich Bescheinigung und zugehöriger Unterlagen | H4: einmalig | I4: 1 | J4: 60 | K4: 1 | L4: 50 | M4: 50 | N4: QZBW – Zusatzanforderungen Wein 2025; Bescheinigung über GVO-Freiheit | O4: QZBW ZA Wein 2025, S. 3, Abschnitt Gentechnik | P4: Produkte mit dem Qualitätszeichen müssen die Anforderungen für die Kennzeichnung „Ohne Gentechnik“ erfüllen.
A5: QZ-0004 | B5: QZBW | C5: Traubenerzeuger / landwirtschaftlicher Betrieb | D5: Traubenerzeuger; Bezugsform: Gruppe | E5: Ausfüllen von Checklisten und Formulare | F5: Datenschutzhinweise zur Teilnahmevereinbarung lesen und unterzeichnen | G5: Dokumentierte Kenntnisnahme der Datenschutzhinweise zur Teilnahmevereinbarung | H5: einmalig | I5: 1 | J5: 15 | K5: 0.25 | L5: 50 | M5: 12.5 | N5: QZBW – Datenschutzhinweise zur Teilnahmevereinbarung, Stand 02.07.2021 | O5: Datenschutzhinweise Teilnahmevereinbarung QZBW, S. 1, Abschnitt 4 | P5: Ihre personenbezogenen Daten werden erhoben, um die Teilnahmevereinbarung abschließen und erfüllen zu können.
A6: QZ-0016 | B6: QZBW | C6: Genossenschaft / zentrale Einrichtung / Zeichennutzer | D6: Administrative Tätigkeiten im QMS der Erzeugergruppe | E6: Verträge | F6: Teilnahmevereinbarung mit dem Gruppenmitglied ausfüllen, unterzeichnen und ablegen | G6: Unterzeichnete Teilnahmevereinbarung mit dem Gruppenmitglied | H6: einmalig | I6: 1 | J6: 15 | K6: 0.25 | L6: 50 | M6: 12.5 | N6: QZBW – Anforderungen an Erzeugergruppen, Stand 01.01.2023 | O6: Anforderungen an Erzeugergruppen 2023, S. 5, Abschnitt 3.2.1 | P6: Die Erzeugergruppe hat mit jedem Mitglied eine gültige Teilnahmevereinbarung QZBW abgeschlossen.
A7: QZ-0017 | B7: QZBW | C7: Genossenschaft / zentrale Einrichtung / Zeichennutzer | D7: Administrative Tätigkeiten als Zeichennutzer | E7: Verträge | F7: Zeichennutzungsvertrag lesen, unterzeichnen und ablegen | G7: Unterzeichneter Zeichennutzungsvertrag | H7: einmalig | I7: 1 | J7: 30 | K7: 0.5 | L7: 50 | M7: 25 | N7: QZBW – Programmbestimmungen, Stand 01.01.2025 | O7: Programmbestimmungen QZBW 2025, S. 34, Abschnitt 10.2 | P7: Die Teilnahme als Zeichennutzer ist nur auf der Grundlage eines Zeichennutzungsvertrages mit einem Lizenznehmer möglich.
A8: QZ-0018 | B8: QZBW | C8: Genossenschaft / zentrale Einrichtung / Zeichennutzer | D8: Administrative Tätigkeiten als Zeichennutzer | E8: Ausfüllen von Checklisten und Formulare | F8: Datenschutzhinweise zum Zeichennutzungsvertrag lesen und unterzeichnen | G8: Dokumentierte Kenntnisnahme der Datenschutzhinweise zum Zeichennutzungsvertrag | H8: einmalig | I8: 1 | J8: 7.5 | K8: 0.125 | L8: 50 | M8: 6.25 | N8: QZBW – Datenschutzhinweise zum Zeichennutzungsvertrag, Stand 02.07.2021 | O8: Datenschutzhinweise Zeichennutzungsvertrag QZBW, S. 1, Abschnitt 4 | P8: Ihre personenbezogenen Daten werden verarbeitet, um den Zeichennutzungsvertrag abschließen und erfüllen zu können.
A9: QZ-0019 | B9: QZBW | C9: Genossenschaft / zentrale Einrichtung / Zeichennutzer | D9: Administrative Tätigkeiten im QMS der Erzeugergruppe | E9: Ausfüllen von Checklisten und Formulare | F9: Excel-Meldedatei für jedes Gruppenmitglied ausfüllen und übermitteln | G9: Vollständige Excel-Meldedatei für jedes Gruppenmitglied | H9: einmalig | I9: 1 | J9: 240 | K9: 4 | L9: 30 | M9: 120 | N9: QZBW – Anforderungen an Erzeugergruppen, Stand 01.01.2023 | O9: Anforderungen an Erzeugergruppen 2023, S. 6, Abschnitt 3.2.3. Die Richtlinie verlangt das aktuelle Mitgliederverzeichnis, jedoch nicht wörtlich das Dateiformat Excel. | P9: Die Erzeugergruppe hat ein Mitgleiderverzeichnis mit folgenden Stammdaten zu führen: […]
A10: QZ-0020 | B10: QZBW | C10: Genossenschaft / zentrale Einrichtung / Zeichennutzer | D10: Administrative Tätigkeiten als Zeichennutzer | E10: Eigenkontrolle als Zeichennutzer | F10: Eigenkontrollcheckliste des Zeichennutzers ausfüllen und ablegen | G10: Vollständig bearbeitete Eigenkontrollcheckliste des Zeichennutzers | H10: einmalig | I10: 1 | J10: 60 | K10: 1 | L10: 30 | M10: 30 | N10: QZBW – Eigenkontrolle Zeichennutzer: Wein, Sekt und Perlwein, Version 2024 | O10: Eigenkontrolle Zeichennutzer – Wein 2024, S. 1, Abschnitt 1.2 | P10: Zur Einhaltung der QZBW-Bestimmungen regelmäßig (mind. jährlich) durchgeführt und dokumentiert (Eigenkontrollchecklisten aufbewahrt).
A11: QZ-0021 | B11: QZBW | C11: Genossenschaft / zentrale Einrichtung / Zeichennutzer | D11: Administrative Tätigkeiten im QMS der Erzeugergruppe | E11: Interne Prüfungen innerhalb der Gruppe | F11: Eigenkontrollcheckliste des Traubenerzeugers prüfen und Prüfergebnis dokumentieren | G11: Geprüfte Eigenkontrollcheckliste des Traubenerzeugers | H11: einmalig | I11: 1 | J11: 120 | K11: 2 | L11: 30 | M11: 60 | N11: QZBW – Anforderungen an Erzeugergruppen, Stand 01.01.2023 | O11: Anforderungen an Erzeugergruppen 2023, S. 8, Abschnitt 4.1.1 | P11: Die Einhaltung der Anforderungen muss über ein qualifiziertes internes Audit bzw. Kontrolle mindestens einmal je Kalenderjahr überprüft und anhand einer Checkliste dokumentiert werden.
A12: QZ-0022 | B12: QZBW | C12: Genossenschaft / zentrale Einrichtung / Zeichennutzer | D12: Administrative Tätigkeiten im QMS der Erzeugergruppe | E12: Interne Prüfungen innerhalb der Gruppe | F12: Maßnahmenpläne prüfen und Prüfergebnis dokumentieren | G12: Geprüfte Maßnahmenpläne | H12: einmalig | I12: 1 | J12: 30 | K12: 0.5 | L12: 30 | M12: 15 | N12: QZBW – Anforderungen an Erzeugergruppen, Stand 01.01.2023 | O12: Anforderungen an Erzeugergruppen 2023, S. 9, Abschnitt 4.2.1; Schreibweise „inklusiv“ entspricht dem Original | P12: Für alle in internen Audits/Kontrollen festgestellten C- und D-Bewertungen sind Korrekturmaßnahmen inklusiv angemessener Fristen eingetragen.
A13: QZ-0023 | B13: QZBW | C13: Genossenschaft / zentrale Einrichtung / Zeichennutzer | D13: Administrative Tätigkeiten im QMS der Erzeugergruppe | E13: Interne Prüfungen innerhalb der Gruppe | F13: Pflanzenschutzaufzeichnungen prüfen und Prüfergebnis dokumentieren | G13: Geprüfte Pflanzenschutzaufzeichnungen | H13: einmalig | I13: 1 | J13: 60 | K13: 1 | L13: 30 | M13: 30 | N13: QZBW – Anforderungen an Erzeugergruppen, Stand 01.01.2023 | O13: Anforderungen an Erzeugergruppen 2023, S. 8, Abschnitt 4.1.2; umfasst die anwendbaren Pflanzenschutzanforderungen | P13: Interne Checklisten müssen alle anwendbaren Standardanforderungen enthalten.
... A26: QZ-0045 | B26: QZBW | C26: Genossenschaft / zentrale Einrichtung / Zeichennutzer | D26: Administrative Tätigkeiten im QMS der Erzeugergruppe | E26: QMS-Dokumentation und -lenkung | F26: QMS-Verfahren, Arbeitsanweisungen, Formulare und Aufzeichnungen ablegen, auf Aktualität prüfen und pflegen | G26: Aktuelle, versionierte und vollständig abgelegte QMS-Unterlagen der Erzeugergruppe | H26: fortlaufend | I26: 1 | J26: 240 | K26: 4 | L26: 30 | M26: 120 | N26: QZBW – Anforderungen an Erzeugergruppen, Stand 01.01.2023 | O26: S. 10-11, Abschnitte 7.1.1 und 7.1.2 | P26: Das QMS muss durch Verfahren, Arbeitsanweisungen, Formulare und ggf. weitere Aufzeichnungen entsprechend seiner Größe angemessen dokumentiert sein. Die Dokumente werden regelmäßig auf Aktualität überprüft.
A27: QZ-0046 | B27: QZBW | C27: Kontroll-/Zertifizierungsstelle | D27: Externe Kontrolle; Bezugsform: Gruppe | E27: Stichprobenkontrollen | F27: QMS einschließlich interner Kontrollen anhand der Unterlagen verifizieren und Ergebnis dokumentieren | G27: Verifiziertes QMS einschließlich interner Kontrollen | H27: jährlich; gruppenfix, anteilig je Mitglied (n=150) | I27: =1/Annahmen!$C$77 -> 0.0066666667 | J27: 240 | K27: =I27*J27/60 -> 0.026666667 | L27: 30 | M27: =K27*L27 -> 0.8 | N27: QZBW – Anforderungen an Erzeugergruppen, Stand 01.01.2023 | O27: Anforderungen an Erzeugergruppen 2023, S. 5, Abschnitt 3.1.4 | P27: Das interne Kontrollsystem ist wirksam. Es stellt sicher, dass alle Standorte und alle Mitglieder die Standardanforderungen erfüllen.
A28: QZ-0047 | B28: QZBW | C28: Kontroll-/Zertifizierungsstelle | D28: Externe Kontrolle; Bezugsform: Gruppe | E28: Ausfüllen von Checklisten und Formulare | F28: Prüfergebnisse dokumentieren, an auditierten Betrieb und Lizenznehmer übermitteln sowie Quartalsbericht an die MBW erstellen | G28: Prüfbericht beziehungsweise Auditprotokoll je Audit und zusammenfassender elektronischer Quartalsbericht | H28: fortlaufend und vierteljährlich; 240 Min. als Gesamtmodellwert je Jahr; gruppenfix, anteilig je Mitglied (n=150) | I28: =1/Annahmen!$C$77 -> 0.0066666667 | J28: 240 | K28: =I28*J28/60 -> 0.026666667 | L28: 30 | M28: =K28*L28 -> 0.8 | N28: QZBW – Programmbestimmungen, Stand 01.01.2026 | O28: S. 40, Abschnitt 12.5 | P28: Über die Zertifizierungstätigkeit ist regelmäßig zum Quartalsende ein zusammenfassender Bericht zu erstellen.
A29: QZ-0052 | B29: QZBW | C29: Genossenschaft / zentrale Einrichtung / Zeichennutzer | D29: Administrative Tätigkeiten als Zeichennutzer | E29: Archivierung von Nachweisen | F29: QZBW-Qualitätsnachweis beschaffen und für die Eigen- beziehungsweise Zertifizierungskontrolle bereithalten | G29: QZBW-Qualitätsnachweis für Wein, Sekt und Perlwein durch Gütezeichen beziehungsweise Qualitätsprüfung gemäß den Zusatzanforderungen Wein | H29: jährlich | I29: 1 | J29: 30 | K29: 0.5 | L29: 30 | M29: 15 | N29: QZBW – Zusatzanforderungen Wein 2025 | O29: S. 7, Abschnitt Qualitätsprüfungen | P29: „Der Qualitätsnachweis … erfolgt regelmäßig durch ein Gütezeichen bzw. durch die Qualitätsprüfung.“
A30: QZ-0053 | B30: QZBW | C30: Genossenschaft / zentrale Einrichtung / Zeichennutzer | D30: Administrative Tätigkeiten im QMS der Erzeugergruppe | E30: Mitglieder- und Zulassungsmanagement | F30: Verfahren zur Aufnahme neuer Mitglieder pflegen und Neuaufnahme dokumentieren | G30: Dokumentiertes Verfahren und vollständiger Nachweis der Aufnahme neuer Mitgliedsbetriebe | H30: bei Aufnahme | I30: 1 | J30: 30 | K30: 0.5 | L30: 30 | M30: 15 | N30: QZBW - Anforderungen an Erzeugergruppen, Stand 01.01.2023 | O30: S. 6, Abschnitt 3.2.4 | P30: Es muss ein dokumentiertes Verfahren über die Aufnahme neuer Mitgliedsbetriebe geben.
A31: QZ-0054 | B31: QZBW | C31: Genossenschaft / zentrale Einrichtung / Zeichennutzer | D31: Administrative Tätigkeiten im QMS der Erzeugergruppe | E31: Qualifikation und Schulung | F31: Qualifikations-, Zulassungs- und Begleitnachweise interner Auditoren und Kontrolleure pflegen | G31: Aktuelle Qualifikations-, Zulassungs- und Begleitnachweise der internen Auditoren und Kontrolleure | H31: bei Benennung und Änderung | I31: 1 | J31: 30 | K31: 0.5 | L31: 30 | M31: 15 | N31: QZBW - Anforderungen an Erzeugergruppen, Stand 01.01.2023 | O31: S. 6-7, Abschnitte 3.3.1 und 3.3.2 | P31: Bevor interne Audits/Kontrollen selbstständig durchgeführt werden, muss der interne Auditor/Kontrolleur mindestens ein/e Audit/Kontrolle als Beobachter begleitet haben.
A32: QZ-0055 | B32: QZBW | C32: Genossenschaft / zentrale Einrichtung / Zeichennutzer | D32: Administrative Tätigkeiten im QMS der Erzeugergruppe | E32: Qualifikation und Schulung | F32: Schulungen planen sowie Inhalte und Teilnehmende dokumentieren | G32: Regelmäßige und vollständig dokumentierte Schulungen für Personal und Mitglieder | H32: jährlich | I32: 1 | J32: 60 | K32: 1 | L32: 30 | M32: 30 | N32: QZBW - Anforderungen an Erzeugergruppen, Stand 01.01.2023 | O32: S. 7, Abschnitt 3.3.3 | P32: Die Mitarbeiter/das Personal und die Mitglieder der Erzeugergruppe werden regelmäßig geschult. Die Durchführung der Schulungen ist dokumentiert.
A33: QZ-0056 | B33: QZBW | C33: Genossenschaft / zentrale Einrichtung / Zeichennutzer | D33: Administrative Tätigkeiten im QMS der Erzeugergruppe | E33: Interne Prüfungen innerhalb der Gruppe | F33: Interne Audits terminieren und Auditzeitplan pflegen | G33: Fristgerechter und dokumentierter Zeitplan der internen Audits und Kontrollen | H33: jährlich | I33: 1 | J33: 30 | K33: 0.5 | L33: 30 | M33: 15 | N33: QZBW - Anforderungen an Erzeugergruppen, Stand 01.01.2023 | O33: S. 8, Abschnitte 4.1.5 bis 4.1.7 | P33: Interne Audits/Kontrollen können in Teilaudits erfolgen. In diesem Fall muss ein Zeitplan vorliegen.
A34: QZ-0057 | B34: QZBW | C34: Genossenschaft / zentrale Einrichtung / Zeichennutzer | D34: Administrative Tätigkeiten im QMS der Erzeugergruppe | E34: Interne Prüfungen innerhalb der Gruppe | F34: Mitgliedsfreigabe im Vier-Augen-Prinzip prüfen und dokumentieren | G34: Dokumentierte Freigabe jedes Mitglieds im Vier-Augen-Prinzip | H34: jährlich je Mitglied | I34: 1 | J34: 15 | K34: 0.25 | L34: 30 | M34: 7.5 | N34: QZBW - Anforderungen an Erzeugergruppen, Stand 01.01.2023 | O34: S. 8, Abschnitt 4.1.8 | P34: Diese Freigabe ist dokumentiert.
A35: QZ-0058 | B35: QZBW | C35: Genossenschaft / zentrale Einrichtung / Zeichennutzer | D35: Administrative Tätigkeiten im QMS der Erzeugergruppe | E35: Rückverfolgbarkeits- und Plausibilitätsprüfung | F35: Rückverfolgbarkeitssystem anhand eines Warenbeispiels testen und Ergebnis dokumentieren | G35: Mindestens jährlich getestetes und dokumentiertes Rückverfolgbarkeitssystem | H35: jährlich | I35: 1 | J35: 60 | K35: 1 | L35: 30 | M35: 30 | N35: QZBW - Anforderungen an Erzeugergruppen, Stand 01.01.2023 | O35: S. 10, Abschnitt 6.1.2 | P35: Das System muss mindestens jährlich getestet werden. Der Test ist zu dokumentieren.
A36: QZ-0059 | B36: QZBW | C36: Genossenschaft / zentrale Einrichtung / Zeichennutzer | D36: Administrative Tätigkeiten als Zeichennutzer | E36: Datenaufzeichnung und -pflege | F36: Warenflüsse zwischen QZBW- und Nicht-QZBW-Ware trennen und nachvollziehbar dokumentieren | G36: Nachvollziehbare Trennung der Warenflüsse zwischen QZBW- und Nicht-QZBW-Ware in der Weinbereitung | H36: jährlich (Modellannahme für fortlaufende Pflicht) | I36: 1 | J36: 120 | K36: 2 | L36: 25 | M36: 50 | N36: QZBW – Zusatzanforderungen Wein, Stand 2025 | O36: S. 7, Abschnitt III.6 | P36: Wein, Sekt und Perlwein für die Vermarktung unter dem Qualitätszeichen ist eindeutig und nachvollziehbar zu kennzeichnen. Ware, die nicht unter dem Qualitätszeichen Baden-Württemberg vermarktet wird, ist im gesamten Betriebsablauf von der Programmware nachvollziehbar getrennt zu führen.
A37: QZ-0060 | B37: QZBW | C37: Traubenerzeuger / landwirtschaftlicher Betrieb | D37: Traubenerzeuger; Bezugsform: Gruppe | E37: Archivierung von Nachweisen | F37: Vorhandene Betriebsnachweise für das QMS zusammenstellen und der Erzeugergruppe übermitteln | G37: Vollständig zusammengestelltes und an die Erzeugergruppe übermitteltes QMS-Nachweispaket | H37: jährlich | I37: 1 | J37: 30 | K37: 0.5 | L37: 50 | M37: 25 | N37: QZBW – Zusatzanforderungen Wein, Stand 2025; Teilnahmevereinbarung Gruppenzertifizierung, Stand 2023 | O37: ZA Wein 2025, S. 6, Abschnitt Dokumentation; Teilnahmevereinbarung GZ 2023, S. 1, Ziff. I.4 | P37: Vor Anlieferung der Ernte […] muss die Dokumentation (Betriebsheft) bei der jeweiligen genossenschaftlichen oder privaten Kellerei […] zur Prüfung vorgelegt werden.
A38: QZ-0061 | B38: QZBW | C38: Traubenerzeuger / landwirtschaftlicher Betrieb | D38: Traubenerzeuger; Bezugsform: Gruppe | E38: Festlegung und Nachverfolgung von Korrekturmaßnahmen | F38: Umsetzung von Korrekturmaßnahmen dokumentieren und der Erzeugergruppe melden | G38: Dokumentierter Umsetzungsnachweis zu festgelegten Korrekturmaßnahmen und Mitteilung an die Erzeugergruppe | H38: bei Bedarf | I38: 1 | J38: 15 | K38: 0.25 | L38: 50 | M38: 12.5 | N38: QZBW – Teilnahmevereinbarung Gruppenzertifizierung (pflanzliche Bereiche), Stand 2023 | O38: S. 2, Ziff. I.4–5 | P38: Bei […] im Rahmen der internen Kontrolle festgestellten Mängeln, geeignete Abhilfe- und Korrekturmaßnahmen einzuleiten und diese zu dokumentieren.
A39: QZ-0062 | B39: QZBW | C39: Genossenschaft / zentrale Einrichtung / Zeichennutzer | D39: Administrative Tätigkeiten im QMS der Erzeugergruppe | E39: Verträge | F39: Kontrollvertrag beziehungsweise Kontrollauftrag prüfen, unterzeichnen und ablegen | G39: Dokumentierte Beauftragung einer zugelassenen Zertifizierungsstelle für die externe Gruppenkontrolle | H39: einmalig | I39: 1 | J39: 30 | K39: 0.5 | L39: 50 | M39: 25 | N39: QZBW – Teilnahmevereinbarung Gruppenzertifizierung (pflanzliche Bereiche), Stand 2023 | O39: S. 1, Ziff. I.4 | P39: Die regelmäßige Inspektion, die Überwachung und ggf. die Zertifizierung erfolgen durch eine […] zugelassene Zertifizierungsstelle im Auftrag des gruppenführenden Unternehmens.
A40: QZ-0063 | B40: QZBW | C40: Genossenschaft / zentrale Einrichtung / Zeichennutzer | D40: Administrative Tätigkeiten im QMS der Erzeugergruppe | E40: QMS-Dokumentation und -lenkung | F40: QMS-Kontrollunterlagen zusammenstellen und der Zertifizierungsstelle bereitstellen | G40: Vollständiges, prüffähiges QMS-Kontrollpaket für die externe Zertifizierungsstelle | H40: jährlich | I40: 1 | J40: 60 | K40: 1 | L40: 30 | M40: 30 | N40: QZBW – Anforderungen an Erzeugergruppen, Stand 01.01.2023 | O40: S. 8, Abschnitt 4.1.3; S. 10–11, Abschnitte 7.1.1–7.1.2 | P40: Die Berichte (ausgefüllte Checklisten) interner Audits/Kontrollen sind vollständig und aussagekräftig. Aufzeichnungen der Nachverfolgung von Korrekturmaßnahmen müssen vorliegen.
A41: QZ-0064 | B41: QZBW | C41: Kontroll-/Zertifizierungsstelle | D41: Externe Kontrolle; Bezugsform: Gruppe | E41: Stichprobenkontrollen | F41: Externen QMS-Kontrolltermin abstimmen und erforderliche Kontrollunterlagen anfordern | G41: Abgestimmter Termin und angefordertes Kontrollpaket für die externe QMS-Prüfung | H41: jährlich; gruppenfix, anteilig je Mitglied (n=150) | I41: =1/Annahmen!$C$77 -> 0.0066666667 | J41: 30 | K41: =I41*J41/60 -> 0.0033333333 | L41: 30 | M41: =K41*L41 -> 0.1 | N41: QZBW – Anforderungen an Erzeugergruppen, Stand 01.01.2023 | O41: S. 8, Abschnitt 4.1.5 | P41: Die internen Audits/Kontrollen müssen vor der externen (neutralen) Kontrolle durch die Zertifizierungsstelle abgeschlossen sein.
A42: QZ-0065 | B42: QZBW | C42: Kontroll-/Zertifizierungsstelle | D42: Externe Kontrolle; Bezugsform: Gruppe | E42: Ausfüllen von Checklisten und Formulare | F42: Zertifizierungsentscheidung dokumentieren und Gruppenzertifikat beziehungsweise Zertifikatsdaten übermitteln | G42: Dokumentierte Zertifizierungsentscheidung und übermitteltes Gruppenzertifikat beziehungsweise Zertifikatsdaten | H42: jährlich; gruppenfix, anteilig je Mitglied (n=150) | I42: =1/Annahmen!$C$77 -> 0.0066666667 | J42: 30 | K42: =I42*J42/60 -> 0.0033333333 | L42: 30 | M42: =K42*L42 -> 0.1 | N42: QZBW – Programmbestimmungen, Stand 01.01.2025; Teilnahmevereinbarung Gruppenzertifizierung, Stand 2023 | O42: Programmbestimmungen QZBW 2025, S. 9, Abschnitt 3.4 | P42: Die Erzeugergruppe ist als juristische Einheit der Zertifikatinhaber und fungiert als Zeichennutzer.
A43: QZ-0066 | B43: QZBW | C43: Genossenschaft / zentrale Einrichtung / Zeichennutzer | D43: Administrative Tätigkeiten im QMS der Erzeugergruppe | E43: Archivierung von Nachweisen | F43: Gruppenzertifikat prüfen, intern zuordnen und im QMS ablegen | G43: Geprüftes und im QMS abgelegtes Gruppenzertifikat | H43: jährlich | I43: 1 | J43: 15 | K43: 0.25 | L43: 30 | M43: 7.5 | N43: QZBW – Programmbestimmungen, Stand 01.01.2025 | O43: S. 9, Abschnitt 3.4 | P43: Die Erzeugergruppe ist als juristische Einheit der Zertifikatinhaber und fungiert als Zeichennutzer.
A44: QZ-0067 | B44: QZBW | C44: Externer Lizenznehmer | D44: Lizenznahme der Erzeugergruppe / Zeichennutzerin | E44: Verträge | F44: Zeichennutzungsvertrag der Erzeugergruppe prüfen und gegenzeichnen sowie Programmanmeldung weiterleiten | G44: Gegengezeichneter Zeichennutzungsvertrag und programmgemäß registrierte Erzeugergruppe | H44: einmalig | I44: 1 | J44: 60 | K44: 1 | L44: 30 | M44: 30 | N44: QZBW – Teilnahmevereinbarung Gruppenzertifizierung (pflanzliche Bereiche), Stand 2023; Programmbestimmungen QZBW 2025 | O44: Teilnahmevereinbarung GZ 2023, S. 2, Ziff. II.2; Programmbestimmungen 2025, Abschnitt 3.4 | P44: Es stellt seinerseits die ordentliche Teilnahme am Qualitätszeichen Baden-Württemberg durch den Abschluss eines Zeichennutzungsvertrages mit einem Lizenznehmer sicher.
A45: QZ-0068 | B45: QZBW | C45: Kontroll-/Zertifizierungsstelle | D45: Externe Kontrolle; Bezugsform: Zeichennutzer | E45: Kontrollvorbereitung | F45: Jährliche Zeichennutzerkontrolle terminieren und programmspezifische Unterlagen anfordern | G45: Abgestimmter Termin und vollständiges Kontrollpaket der Genossenschaft als Zeichennutzerin | H45: jährlich; gruppenfix, anteilig je Mitglied (n=150) | I45: =1/Annahmen!$C$77 -> 0.0066666667 | J45: 15 | K45: =I45*J45/60 -> 0.0016666667 | L45: 30 | M45: =K45*L45 -> 0.05 | N45: QZBW – Programmbestimmungen, Stand 01.01.2026 | O45: S. 24, Abschnitt 6.9; S. 39, Abschnitt 12.3; Zeitansatz siehe ANN-046 | P45: Winzergenossenschaft, Kellerei: 100 %.
A46: QZ-0069 | B46: QZBW | C46: Kontroll-/Zertifizierungsstelle | D46: Externe Kontrolle; Bezugsform: Zeichennutzer | E46: Dokumentenprüfung und Kontrolldokumentation | F46: Eigenkontrollsystem, Produkt- und Qualitätsnachweise, Waren- und Herkunftsdokumentation, Rückverfolgbarkeit und Kennzeichnung prüfen und Kontrollcheckliste vervollständigen | G46: Dokumentierte jährliche Zeichennutzerkontrolle mit bewerteten Prüfpunkten und nachvollziehbarem Ergebnis | H46: jährlich; gruppenfix, anteilig je Mitglied (n=150) | I46: =1/Annahmen!$C$77 -> 0.0066666667 | J46: 60 | K46: =I46*J46/60 -> 0.0066666667 | L46: 30 | M46: =K46*L46 -> 0.2 | N46: QZBW – Programmbestimmungen, Stand 01.01.2026 | O46: S. 18, Abschnitt 6.2.1; S. 39, Abschnitt 12.3; Zeitansatz siehe ANN-047 | P46: Kontrolle/Überprüfung des Eigenkontrollsystems und der Dokumentationen.
A47: QZ-0070 | B47: QZBW | C47: Kontroll-/Zertifizierungsstelle | D47: Externe Kontrolle; Bezugsform: Mitgliederstichprobe | E47: Stichprobenplanung | F47: Risikobasierte Mitgliederstichprobe auswählen und jährlichen Kontrollplan dokumentieren | G47: Nachvollziehbar ausgewählte Stichprobe von 13 Mitgliedern und dokumentierter Kontrollplan | H47: jährlich; gruppenfix, anteilig je Mitglied (n=150) | I47: =1/Annahmen!$C$77 -> 0.0066666667 | J47: 30 | K47: =I47*J47/60 -> 0.0033333333 | L47: 30 | M47: =K47*L47 -> 0.1 | N47: QZBW – Programmbestimmungen, Stand 01.01.2026 | O47: S. 19–20, Abschnitt 6.3; Zeitansatz siehe ANN-043 | P47: Der Mindestumfang der Stichprobe ist die Quadratwurzel der Zahl der Mitglieder.
A48: QZ-0071 | B48: QZBW | C48: Kontroll-/Zertifizierungsstelle | D48: Externe Kontrolle; Bezugsform: Mitgliederstichprobe | E48: Administrative Kontrollvorbereitung | F48: Termin und Unterlagen je ausgewähltem Mitglied koordinieren und Kontrollakte vorbereiten | G48: Vorbereitete Kontrollakten für 13 externe Mitgliederkontrollen | H48: jährlich; 13 Stichproben je Gruppe, anteilig je Mitglied (n=150) | I48: =Annahmen!$C$78/Annahmen!$C$77 -> 0.086666667 | J48: 15 | K48: =I48*J48/60 -> 0.021666667 | L48: 30 | M48: =K48*L48 -> 0.65 | N48: QZBW – Programmbestimmungen, Stand 01.01.2026 | O48: S. 19–20, Abschnitt 6.3; Zeitansatz siehe ANN-044 | P48: Die Auswahl soll frühere Kontrollergebnisse und mögliche Beschwerden berücksichtigen.
A49: QZ-0072 | B49: QZBW | C49: Kontroll-/Zertifizierungsstelle | D49: Externe Kontrolle; Bezugsform: Mitgliederstichprobe | E49: Administrative Kontrollnachbereitung | F49: Kontrollcheckliste je Stichprobenmitglied abschließen, Ergebnis und gegebenenfalls Abweichungen dokumentieren und Kontrollakte schließen | G49: Vollständige administrative Abschlussdokumentation für 13 externe Mitgliederkontrollen | H49: jährlich; 13 Stichproben je Gruppe, anteilig je Mitglied (n=150) | I49: =Annahmen!$C$78/Annahmen!$C$77 -> 0.086666667 | J49: 15 | K49: =I49*J49/60 -> 0.021666667 | L49: 30 | M49: =K49*L49 -> 0.65 | N49: QZBW – Programmbestimmungen, Stand 01.01.2026 | O49: S. 40, Abschnitt 12.5; Zeitansatz siehe ANN-045 | P49: Die auditierten Betriebe sind unverzüglich über alle Prüfergebnisse zu unterrichten.
A50: QZ-0073 | B50: QZBW | C50: Externer Lizenznehmer | D50: Laufende teilnehmerbezogene Lizenznehmerverwaltung | E50: Programm- und Vertragsüberwachung | F50: Programminhalte und vertragliche Verpflichtungen der angeschlossenen Teilnehmer laufend überwachen | G50: Nachvollziehbar überwachter Teilnehmerstatus und dokumentierte Einhaltung der programmspezifischen und vertraglichen Pflichten | H50: jährlich; teilnehmerbezogen | I50: =1 -> 1 | J50: =Annahmen!$C$87 -> 10 | K50: =I50*J50/60 -> 0.16666667 | L50: 30 | M50: =K50*L50 -> 5 | N50: QZBW – Programmbestimmungen, Stand 01.01.2026 | O50: S. 8, Abschnitt 3.2; Zeitansatz siehe ANN-050 | P50: Sie gewährleisten die ordnungsgemäße Umsetzung und Überwachung der Programminhalte bei den ihnen vertraglich angeschlossenen Erzeugern und Zeichennutzern.
A51: QZ-0074 | B51: QZBW | C51: Externer Lizenznehmer | D51: Laufende teilnehmerbezogene Lizenznehmerverwaltung | E51: Kontrollorganisation und -überwachung | F51: Vorgesehene Kontrollen veranlassen und deren Durchführung administrativ überwachen | G51: Beauftragte und statusseitig nachverfolgte Kontrollen bei angeschlossenen Erzeugern und Zeichennutzern | H51: jährlich; teilnehmerbezogen | I51: =1 -> 1 | J51: =Annahmen!$C$88 -> 15 | K51: =I51*J51/60 -> 0.25 | L51: 30 | M51: =K51*L51 -> 7.5 | N51: QZBW – Programmbestimmungen, Stand 01.01.2026 | O51: S. 22, Abschnitte 6.7–6.8; Zeitansatz siehe ANN-051 | P51: Hierbei werden insbesondere die Lizenznehmer regelmäßig dahingehend überprüft, ob sie ihren vertraglichen Pflichten zur Veranlassung und Überwachung von Kontrollen […] nachkommen.
A52: QZ-0075 | B52: QZBW | C52: Externer Lizenznehmer | D52: Laufende teilnehmerbezogene Lizenznehmerverwaltung | E52: Prüfergebnis- und Maßnahmenmanagement | F52: Prüfergebnisse zuordnen, Teilnehmerstatus aktualisieren und gewöhnliche Korrekturhinweise nachverfolgen | G52: Vollständig zugeordnete Prüfberichte und nachvollziehbar nachgehaltene Standardabweichungen beziehungsweise Korrekturhinweise | H52: jährlich; teilnehmerbezogen | I52: =1 -> 1 | J52: =Annahmen!$C$89 -> 15 | K52: =I52*J52/60 -> 0.25 | L52: 30 | M52: =K52*L52 -> 7.5 | N52: QZBW – Programmbestimmungen, Stand 01.01.2026 | O52: S. 40, Abschnitt 12.5; Zeitansatz siehe ANN-052 | P52: Zertifizierungsstellen sind verpflichtet, […] den verantwortlichen Lizenznehmer fortlaufend unverzüglich über alle Prüfergebnisse zu unterrichten.
...

Sheet Anford_BioZBW_zert_spez
A1: ID | B1: Programm | C1: Akteur | D1: Rolle | E1: Prozesskategorie | F1: Administrative Tätigkeit (Objekt + Verb) | G1: Fachliche Anforderung / erforderlicher Nachweis | H1: Häufigkeit | I1: Fallzahl / Bezugsgröße | J1: Zeitaufwand je Vorgang (Min.) | K1: Gesamter Zeitaufwand (Std.) | L1: Stundensatz (EUR/Std.) | M1: Arbeitszeitkosten (EUR) | N1: Quelldokument | O1: Genaue Fundstelle | P1: Wörtliches Zitat
A2: BIO-0001 | B2: BioZBW | C2: Traubenerzeuger / landwirtschaftlicher Betrieb | D2: Traubenerzeuger; Bezugsform: Gruppe | E2: Verträge | F2: Teilnahmeerklärung gegenüber der Genossenschaft als Zeichennutzerin und Unternehmergruppe prüfen, unterzeichnen und übermitteln | G2: Unterzeichnete beziehungsweise vertraglich integrierte Teilnahmeerklärung des Traubenerzeugers gegenüber der Genossenschaft als Zeichennutzerin und Unternehmergruppe | H2: einmalig | I2: 1 | J2: 15 | K2: 0.25 | L2: 50 | M2: 12.5 | N2: BioZBW – Programmbestimmungen, Stand 01.01.2026; Verordnung (EU) 2018/848; Delegierte Verordnung (EU) 2021/715 | O2: S. 22–23, Abschnitte 9.1–9.2; VO (EU) 2018/848, Art. 36 | P2: Landwirtschaftliche Erzeugerbetriebe (Erzeuger) müssen über den Zeichennutzer eine Teilnahmeerklärung zum Biozeichen Baden-Württemberg abgeben. […] Bei bestehenden vertraglichen Beziehungen […] ist es möglich, die Inhalte der Teilnahmeerklärung […] als Zusatz oder Bestandteil dieser vertraglichen Regelungen abzuschließen.
A3: BIO-0002 | B3: BioZBW | C3: Traubenerzeuger / landwirtschaftlicher Betrieb | D3: Traubenerzeuger; Bezugsform: Gruppe | E3: Ausfüllen von Checklisten und Formulare | F3: Datenschutzhinweise zur Teilnahmevereinbarung lesen und unterzeichnen | G3: Dokumentierte Kenntnisnahme der Datenschutzhinweise zur Teilnahmevereinbarung | H3: einmalig | I3: 1 | J3: 15 | K3: 0.25 | L3: 50 | M3: 12.5 | N3: BioZBW – Teilnahmeerklärung Erzeuger, Stand 07.12.2017 | O3: Teilnahmeerklärung Erzeuger BioZBW, S. 2, Datenschutzhinweis | P3: Die in der Teilnahmeerklärung angegebenen personenbezogenen Daten […] sind für die Durchführung und Überwachung sowie die Dokumentation im Rahmen des Bio-Zeichens Baden-Württemberg erforderlich.
A4: BIO-0013 | B4: BioZBW | C4: Genossenschaft / zentrale Einrichtung / Zeichennutzer | D4: Administrative Tätigkeiten im QMS der Erzeugergruppe | E4: Verträge | F4: Teilnahmevereinbarung mit dem Gruppenmitglied ausfüllen, unterzeichnen und ablegen | G4: Unterzeichnete Teilnahmevereinbarung mit dem Gruppenmitglied | H4: einmalig | I4: 1 | J4: 15 | K4: 0.25 | L4: 50 | M4: 12.5 | N4: Verordnung (EU) 2018/848; Durchführungsverordnung (EU) 2021/279 | O4: Art. 5 Buchst. b; https://eur-lex.europa.eu/eli/reg/2018/848/oj?locale=de; https://eur-lex.europa.eu/legal-content/DE/ALL/?uri=CELEX%3A32021R0279 | P4: Unterzeichnete Mitgliedsvereinbarungen
A5: BIO-0014 | B5: BioZBW | C5: Genossenschaft / zentrale Einrichtung / Zeichennutzer | D5: Administrative Tätigkeiten als Zeichennutzer | E5: Verträge | F5: Zeichennutzungsvertrag lesen, unterzeichnen und ablegen | G5: Unterzeichneter Zeichennutzungsvertrag | H5: einmalig | I5: 1 | J5: 30 | K5: 0.5 | L5: 50 | M5: 25 | N5: BioZBW – Programmbestimmungen, Stand 01.01.2025 | O5: Programmbestimmungen BioZBW 2025, S. 8, Abschnitt 3.4 | P5: Zeichennutzer sind Verarbeitungs- und Vermarktungsbetriebe […] Dazu schließen sie mit einem Lizenznehmer einen entsprechenden Zeichennutzungsvertrag ab.
A6: BIO-0015 | B6: BioZBW | C6: Genossenschaft / zentrale Einrichtung / Zeichennutzer | D6: Administrative Tätigkeiten als Zeichennutzer | E6: Ausfüllen von Checklisten und Formulare | F6: Datenschutzhinweise zum Zeichennutzungsvertrag lesen und unterzeichnen | G6: Dokumentierte Kenntnisnahme der Datenschutzhinweise zum Zeichennutzungsvertrag | H6: einmalig | I6: 1 | J6: 7.5 | K6: 0.125 | L6: 50 | M6: 6.25 | N6: BioZBW – Datenschutzhinweise zum Zeichennutzungsvertrag, 2024 | O6: Datenschutzhinweise Zeichennutzungsvertrag BioZBW 2024, S. 1, Abschnitt „Zwecke und Rechtsgrundlagen der Verarbeitung“ | P6: Ihre personenbezogenen Daten werden verarbeitet, um den Zeichennutzungsvertrag abschließen und erfüllen zu können.
A7: BIO-0016 | B7: BioZBW | C7: Genossenschaft / zentrale Einrichtung / Zeichennutzer | D7: Administrative Tätigkeiten im QMS der Erzeugergruppe | E7: Ausfüllen von Checklisten und Formulare | F7: Mitglieder- und Meldedatei aktualisieren und jährlich an den Lizenznehmer übermitteln | G7: Aktuelles Mitgliederverzeichnis sowie jährliche Auskunft über die vorliegenden Teilnahmeerklärungen | H7: jährlich sowie bei Änderungen | I7: 1 | J7: 240 | K7: 4 | L7: 30 | M7: 120 | N7: Verordnung (EU) 2018/848; Durchführungsverordnung (EU) 2021/279; BioZBW – Programmbestimmungen, Stand 01.01.2026 | O7: BioZBW-Programmbestimmungen 2026, S. 27, Abschnitt 11.3; VO (EU) 2021/279, Art. 5 Buchst. a | P7: Zeichennutzer […] sind verpflichtet, ihrem Lizenznehmer regelmäßig jährlich zum Stand 31. Oktober […] Auskunft über die bei ihnen vorliegenden Teilnahmeerklärungen von Erzeugern zu geben.
A8: BIO-0017 | B8: BioZBW | C8: Genossenschaft / zentrale Einrichtung / Zeichennutzer | D8: Administrative Tätigkeiten als Zeichennutzer | E8: Eigenkontrolle als Zeichennutzer | F8: Eigenkontrollcheckliste des Zeichennutzers ausfüllen, aktualisieren und ablegen | G8: Durchgängiges Eigenkontrollsystem des Zeichennutzers mit vollständig bearbeiteter Eigenkontrollcheckliste | H8: jährlich (Modellannahme) | I8: 1 | J8: 60 | K8: 1 | L8: 30 | M8: 30 | N8: BioZBW – Programmbestimmungen, Stand 01.01.2026; BioZBW – Eigenkontrolle Zeichennutzer, Version 2024; BioZBW – Zusatzanforderungen für pflanzliche Produkte, Stand 2024 | O8: BioZBW-Programmbestimmungen 2026, S. 14, Abschnitt 6.1; Eigenkontrolle Zeichennutzer 2024; ZA pflanzliche Produkte 2024, S. 8, Abschnitt III.3 | P8: Jeder Zeichennutzer und gegebenenfalls von diesem eingebundene Dienstleister haben ein durchgängiges Eigenkontrollsystem zu führen und mit den vorgegebenen Checklisten nachzuweisen.
A9: BIO-0018 | B9: BioZBW | C9: Genossenschaft / zentrale Einrichtung / Zeichennutzer | D9: Administrative Tätigkeiten im QMS der Erzeugergruppe | E9: Interne Prüfungen innerhalb der Gruppe | F9: Eigenkontrollcheckliste und betriebliche Nachweise des Gruppenmitglieds prüfen, Prüfergebnis dokumentieren und Mitglied freigeben | G9: Geprüfte Eigenkontrollcheckliste und betriebliche Nachweise mit dokumentiertem Prüfergebnis und Freigabestatus | H9: einmalig | I9: 1 | J9: 120 | K9: 2 | L9: 30 | M9: 60 | N9: Verordnung (EU) 2018/848; Durchführungsverordnung (EU) 2021/279 | O9: Art. 36 Abs. 1 Buchst. g; Art. 5 Buchst. c; https://eur-lex.europa.eu/eli/reg/2018/848/oj?locale=de; https://eur-lex.europa.eu/legal-content/DE/ALL/?uri=CELEX%3A32021R0279 | P9: Dokumentierte interne Kontrollen und Kontrollberichte
A10: BIO-0019 | B10: BioZBW | C10: Genossenschaft / zentrale Einrichtung / Zeichennutzer | D10: Administrative Tätigkeiten im QMS der Erzeugergruppe | E10: Interne Prüfungen innerhalb der Gruppe | F10: Maßnahmenpläne prüfen und Prüfergebnis dokumentieren | G10: Geprüfte Maßnahmenpläne | H10: einmalig | I10: 1 | J10: 30 | K10: 0.5 | L10: 30 | M10: 15 | N10: Verordnung (EU) 2018/848; Durchführungsverordnung (EU) 2021/279 | O10: Art. 5 Buchst. f; https://eur-lex.europa.eu/eli/reg/2018/848/oj?locale=de; https://eur-lex.europa.eu/legal-content/DE/ALL/?uri=CELEX%3A32021R0279 | P10: Maßnahmen bei Nichtkonformität und Nachverfolgung
A11: BIO-0020 | B11: BioZBW | C11: Genossenschaft / zentrale Einrichtung / Zeichennutzer | D11: Administrative Tätigkeiten im QMS der Erzeugergruppe | E11: Interne Prüfungen innerhalb der Gruppe | F11: Pflanzenschutzaufzeichnungen prüfen und Prüfergebnis dokumentieren | G11: Geprüfte Pflanzenschutzaufzeichnungen | H11: einmalig | I11: 1 | J11: 60 | K11: 1 | L11: 30 | M11: 30 | N11: Durchführungsverordnung (EU) 2021/279 | O11: Art. 5 Buchst. g; https://eur-lex.europa.eu/legal-content/DE/ALL/?uri=CELEX%3A32021R0279 | P11: Rückverfolgbarkeitsaufzeichnungen zu Betriebsmitteln, Erzeugung, Lagerung und Lieferung
A12: BIO-0021 | B12: BioZBW | C12: Genossenschaft / zentrale Einrichtung / Zeichennutzer | D12: Administrative Tätigkeiten im QMS der Erzeugergruppe | E12: Interne Prüfungen innerhalb der Gruppe | F12: Düngemittelaufzeichnungen prüfen und Prüfergebnis dokumentieren | G12: Geprüfte Düngemittelaufzeichnungen | H12: einmalig | I12: 1 | J12: 60 | K12: 1 | L12: 30 | M12: 30 | N12: Durchführungsverordnung (EU) 2021/279 | O12: Art. 5 Buchst. g; https://eur-lex.europa.eu/legal-content/DE/ALL/?uri=CELEX%3A32021R0279 | P12: Rückverfolgbarkeitsaufzeichnungen zu Betriebsmitteln, Erzeugung, Lagerung und Lieferung
A13: BIO-0022 | B13: BioZBW | C13: Genossenschaft / zentrale Einrichtung / Zeichennutzer | D13: Administrative Tätigkeiten im QMS der Erzeugergruppe | E13: Rückverfolgbarkeits- und Plausibilitätsprüfung | F13: Ernteaufzeichnungen prüfen und Prüfergebnis dokumentieren | G13: Geprüfte Ernteaufzeichnungen | H13: einmalig | I13: 1 | J13: 30 | K13: 0.5 | L13: 30 | M13: 15 | N13: Durchführungsverordnung (EU) 2021/279 | O13: Art. 5 Buchst. g; https://eur-lex.europa.eu/legal-content/DE/ALL/?uri=CELEX%3A32021R0279 | P13: Rückverfolgbarkeitsaufzeichnungen zu Betriebsmitteln, Erzeugung, Lagerung und Lieferung
... A25: BIO-0042 | B25: BioZBW | C25: Genossenschaft / zentrale Einrichtung / Zeichennutzer | D25: Administrative Tätigkeiten im QMS der Erzeugergruppe | E25: QMS-Dokumentation und -lenkung | F25: QMS-Verfahren, Unterlagen und Aufzeichnungen erstellen, aktualisieren und bereitstellen | G25: Aktuelle und vollständig verfügbare QMS-Verfahren, Unterlagen und Aufzeichnungen der Unternehmergruppe | H25: fortlaufend | I25: 1 | J25: 240 | K25: 4 | L25: 30 | M25: 120 | N25: Verordnung (EU) 2018/848; Delegierte Verordnung (EU) 2021/715; Durchführungsverordnung (EU) 2021/279 | O25: VO (EU) 2018/848, Art. 36; VO (EU) 2021/715, Art. 1 Nr. 1 Buchst. b und c; VO (EU) 2021/279, Art. 5 | P25: Entwicklung der IKS-Verfahren und Ausarbeitung der entsprechenden Unterlagen und Aufzeichnungen, Aktualisierung und Verfügbar machen dieser für die IKS-Inspektoren und gegebenenfalls die Mitglieder der Gruppe.
A26: BIO-0043 | B26: BioZBW | C26: Kontroll-/Zertifizierungsstelle | D26: Externe Kontrolle; Bezugsform: Gruppe | E26: Stichprobenkontrollen | F26: QMS anhand der Unterlagen verifizieren und Ergebnis dokumentieren | G26: Verifiziertes QMS | H26: jährlich; gruppenfix, anteilig je Mitglied (n=150) | I26: =1/Annahmen!$C$77 -> 0.0066666667 | J26: 240 | K26: =I26*J26/60 -> 0.026666667 | L26: 30 | M26: =K26*L26 -> 0.8 | N26: Verordnung (EU) 2018/848; Durchführungsverordnung (EU) 2021/279 | O26: Art. 36; Art. 7; https://eur-lex.europa.eu/eli/reg/2018/848/oj?locale=de; https://eur-lex.europa.eu/legal-content/DE/ALL/?uri=CELEX%3A32021R0279 | P26: Verifizierung des internen Kontrollsystems
A27: BIO-0044 | B27: BioZBW | C27: Kontroll-/Zertifizierungsstelle | D27: Externe Kontrolle; Bezugsform: Gruppe | E27: Ausfüllen von Checklisten und Formulare | F27: Prüfergebnisse dokumentieren und Quartalsmeldung an die MBW übermitteln | G27: Dokumentierte Prüfergebnisse sowie fristgerechte Quartalsmeldung der Zertifizierungsstelle | H27: vierteljährlich; 240 Min. als Gesamtmodellwert je Jahr; gruppenfix, anteilig je Mitglied (n=150) | I27: =1/Annahmen!$C$77 -> 0.0066666667 | J27: 240 | K27: =I27*J27/60 -> 0.026666667 | L27: 30 | M27: =K27*L27 -> 0.8 | N27: BioZBW – Programmbestimmungen, Stand 01.01.2026; Durchführungsverordnung (EU) 2021/279 | O27: BioZBW-Programmbestimmungen 2026, S. 28, Abschnitt 11.5; VO (EU) 2021/279, Art. 7 | P27: Über die Zertifizierungstätigkeit ist regelmäßig zu einem Quartalsende ein zusammenfassender Bericht zu erstellen. […] Die Berichte müssen jeweils im darauffolgenden Quartal […] bei der MBW abgegeben werden.
A28: BIO-0047 | B28: BioZBW | C28: Genossenschaft / zentrale Einrichtung / Zeichennutzer | D28: Administrative Tätigkeiten im QMS der Erzeugergruppe | E28: Mitglieder- und Zulassungsmanagement | F28: Mitgliederliste mit Kontrollstatus und Versionsstand aktualisieren | G28: Aktuelle Mitgliederliste mit Status, Kontrollangaben und Versionsstand | H28: bei jeder Änderung | I28: 1 | J28: 15 | K28: 0.25 | L28: 30 | M28: 7.5 | N28: Durchführungsverordnung (EU) 2021/279 | O28: Art. 5 Buchst. a und letzter Absatz | P28: Die in Absatz 1 Buchstabe a genannte Liste der Mitglieder wird vom IKS-Verwalter aktualisiert, sobald sich eines der [...] aufgeführten Elemente ändert.
A29: BIO-0048 | B29: BioZBW | C29: Genossenschaft / zentrale Einrichtung / Zeichennutzer | D29: Administrative Tätigkeiten im QMS der Erzeugergruppe | E29: Qualifikation und Schulung | F29: interne QMS-Kontrolleure ernennen sowie Interessenkonflikte und Qualifikation dokumentieren | G29: Dokumentierte Ernennung, Unabhängigkeit und Qualifikation der interne QMS-Kontrolleure | H29: bei Ernennung und jährlich | I29: 1 | J29: 30 | K29: 0.5 | L29: 30 | M29: 15 | N29: Delegierte Verordnung (EU) 2021/715; Durchführungsverordnung (EU) 2021/279 | O29: VO (EU) 2021/715, Art. 1 Nr. 1 Buchst. c Ziff. vii und ix; VO (EU) 2021/279, Art. 5 Buchst. d und j | P29: jährliche Überprüfung der Erklärungen zu Interessenkonflikten der IKS-Inspektoren
A30: BIO-0049 | B30: BioZBW | C30: Genossenschaft / zentrale Einrichtung / Zeichennutzer | D30: Administrative Tätigkeiten im QMS der Erzeugergruppe | E30: Qualifikation und Schulung | F30: interne QMS-Kontrolleure und Mitglieder schulen und Schulungsnachweise pflegen | G30: Jährliche Schulungen der interne QMS-Kontrolleure und dokumentierte Schulungen der Gruppenmitglieder | H30: jährlich | I30: 1 | J30: 60 | K30: 1 | L30: 30 | M30: 30 | N30: Delegierte Verordnung (EU) 2021/715; Durchführungsverordnung (EU) 2021/279 | O30: VO (EU) 2021/715, Art. 1 Nr. 1 Buchst. b Ziff. iv und v; VO (EU) 2021/279, Art. 5 Buchst. d und e | P30: Schulungen der IKS-Inspektoren, die mindestens einmal jährlich stattfinden [...] Schulungen der Mitglieder der Gruppe zu den IKS-Verfahren
A31: BIO-0050 | B31: BioZBW | C31: Genossenschaft / zentrale Einrichtung / Zeichennutzer | D31: Administrative Tätigkeiten im QMS der Erzeugergruppe | E31: Interne Prüfungen innerhalb der Gruppe | F31: Interne Inspektionen terminieren und Inspektionsplan pflegen | G31: Vom QMS-verantwortliche Person geplante und fristgerecht durchgeführte interne Inspektionen | H31: jährlich | I31: 1 | J31: 30 | K31: 0.5 | L31: 30 | M31: 15 | N31: Delegierte Verordnung (EU) 2021/715 | O31: Art. 1 Nr. 1 Buchst. c Ziff. viii | P31: Anberaumung interner Inspektionen und Sicherstellung ihrer angemessenen Durchführung gemäß dem [...] Plan des IKS-Verwalters
A32: BIO-0051 | B32: BioZBW | C32: Genossenschaft / zentrale Einrichtung / Zeichennutzer | D32: Administrative Tätigkeiten im QMS der Erzeugergruppe | E32: Mitglieder- und Zulassungsmanagement | F32: Neue Mitglieder, Produktionseinheiten oder Tätigkeiten prüfen und Zulassung dokumentieren | G32: Dokumentierte Zulassung neuer Mitglieder, Produktionseinheiten und Tätigkeiten | H32: bei Aufnahme oder Änderung | I32: 1 | J32: 30 | K32: 0.5 | L32: 30 | M32: 15 | N32: Delegierte Verordnung (EU) 2021/715 | O32: Art. 1 Nr. 1 Buchst. b Ziff. iii und Buchst. c Ziff. x | P32: Zulassung neuer Mitglieder oder neuer Produktionseinheiten oder neuer Tätigkeiten bestehender Mitglieder
A33: BIO-0052 | B33: BioZBW | C33: Genossenschaft / zentrale Einrichtung / Zeichennutzer | D33: Administrative Tätigkeiten im QMS der Erzeugergruppe | E33: Kontroll-, Abweichungs- und Beschwerdedokumentation | F33: Erhebliche Verstöße, Mitgliedssperren und Vermarktungsverbote an die Kontrollstelle melden | G33: Unverzügliche Meldung erheblicher oder kritischer Verstöße, Sperren und Vermarktungsverbote | H33: bei Bedarf | I33: 1 | J33: 30 | K33: 0.5 | L33: 30 | M33: 15 | N33: Durchführungsverordnung (EU) 2021/279 | O33: Art. 6 | P33: Der IKS-Verwalter teilt der zuständigen Behörde oder gegebenenfalls der Kontrollbehörde oder Kontrollstelle unverzüglich Folgendes mit
A34: BIO-0053 | B34: BioZBW | C34: Traubenerzeuger / landwirtschaftlicher Betrieb | D34: Traubenerzeuger; Bezugsform: Gruppe | E34: Archivierung von Nachweisen | F34: Vorhandene Betriebsnachweise für das QMS zusammenstellen und der Unternehmergruppe übermitteln | G34: Vollständig zusammengestelltes und an die Unternehmergruppe übermitteltes QMS-Nachweispaket | H34: jährlich | I34: 1 | J34: 30 | K34: 0.5 | L34: 50 | M34: 25 | N34: Verordnung (EU) 2018/848; Durchführungsverordnung (EU) 2021/279 | O34: VO (EU) 2018/848, Art. 36; VO (EU) 2021/279, Art. 5 | P34: Der IKS-Verwalter […] führt über jedes Mitglied […] Aufzeichnungen und bewahrt diese auf […] und stellt die erforderlichen Unterlagen für die amtlichen Kontrollen bereit.
A35: BIO-0054 | B35: BioZBW | C35: Traubenerzeuger / landwirtschaftlicher Betrieb | D35: Traubenerzeuger; Bezugsform: Gruppe | E35: Festlegung und Nachverfolgung von Korrekturmaßnahmen | F35: Umsetzung von Korrekturmaßnahmen dokumentieren und der Unternehmergruppe melden | G35: Dokumentierter Umsetzungsnachweis zu festgelegten Korrekturmaßnahmen und Mitteilung an die Unternehmergruppe | H35: bei Bedarf | I35: 1 | J35: 15 | K35: 0.25 | L35: 50 | M35: 12.5 | N35: Durchführungsverordnung (EU) 2021/279 | O35: Art. 5 Buchst. f | P35: Maßnahmen bei Nichtkonformität […] einschließlich des Zeitplans für ihre Durchführung und der Überwachung ihres Abschlusses.
A36: BIO-0055 | B36: BioZBW | C36: Genossenschaft / zentrale Einrichtung / Zeichennutzer | D36: Administrative Tätigkeiten im QMS der Erzeugergruppe | E36: Verträge | F36: Kontrollvertrag beziehungsweise Kontrollauftrag prüfen, unterzeichnen und ablegen | G36: Dokumentierte Beauftragung der Kontrollstelle für die externe Kontrolle der Unternehmergruppe | H36: einmalig | I36: 1 | J36: 30 | K36: 0.5 | L36: 50 | M36: 25 | N36: Verordnung (EU) 2018/848; Durchführungsverordnung (EU) 2021/279 | O36: VO (EU) 2018/848, Art. 36; VO (EU) 2021/279, Art. 7 | P36: Die Gruppe […] unterliegt einem Kontrollsystem für die amtlichen Kontrollen und anderen amtlichen Tätigkeiten.
A37: BIO-0056 | B37: BioZBW | C37: Genossenschaft / zentrale Einrichtung / Zeichennutzer | D37: Administrative Tätigkeiten im QMS der Erzeugergruppe | E37: QMS-Dokumentation und -lenkung | F37: QMS-Kontrollunterlagen zusammenstellen und der Kontrollstelle bereitstellen | G37: Vollständiges, prüffähiges QMS-Kontrollpaket für die externe Kontrollstelle | H37: jährlich | I37: 1 | J37: 60 | K37: 1 | L37: 30 | M37: 30 | N37: Durchführungsverordnung (EU) 2021/279 | O37: Art. 5 und 7 | P37: Der IKS-Verwalter stellt […] die Dokumente und Aufzeichnungen der Gruppe […] zur Verfügung.
A38: BIO-0057 | B38: BioZBW | C38: Kontroll-/Zertifizierungsstelle | D38: Externe Kontrolle; Bezugsform: Gruppe | E38: Stichprobenkontrollen | F38: Externen QMS-Kontrolltermin abstimmen und erforderliche Kontrollunterlagen anfordern | G38: Abgestimmter Termin und angefordertes Kontrollpaket für die externe QMS-Prüfung | H38: jährlich; gruppenfix, anteilig je Mitglied (n=150) | I38: =1/Annahmen!$C$77 -> 0.0066666667 | J38: 30 | K38: =I38*J38/60 -> 0.0033333333 | L38: 30 | M38: =K38*L38 -> 0.1 | N38: Durchführungsverordnung (EU) 2021/279 | O38: Art. 7 | P38: Die zuständige Behörde oder gegebenenfalls die Kontrollbehörde oder Kontrollstelle überprüft jährlich die Einrichtung und Funktionsweise des IKS.
A39: BIO-0058 | B39: BioZBW | C39: Kontroll-/Zertifizierungsstelle | D39: Externe Kontrolle; Bezugsform: Gruppe | E39: Ausfüllen von Checklisten und Formulare | F39: Zertifizierungsentscheidung dokumentieren und Gruppenzertifikat beziehungsweise Zertifikatsdaten übermitteln | G39: Dokumentierte Zertifizierungsentscheidung und übermittelte Zertifikatsdaten für die Unternehmergruppe | H39: jährlich; gruppenfix, anteilig je Mitglied (n=150) | I39: =1/Annahmen!$C$77 -> 0.0066666667 | J39: 30 | K39: =I39*J39/60 -> 0.0033333333 | L39: 30 | M39: =K39*L39 -> 0.1 | N39: Verordnung (EU) 2018/848 | O39: Art. 36 Abs. 2 in Verbindung mit Art. 35 | P39: Das in Artikel 35 genannte Zertifikat wird für die gesamte Gruppe ausgestellt.
A40: BIO-0059 | B40: BioZBW | C40: Genossenschaft / zentrale Einrichtung / Zeichennutzer | D40: Administrative Tätigkeiten im QMS der Erzeugergruppe | E40: Archivierung von Nachweisen | F40: Gruppenzertifikat prüfen, intern zuordnen und im QMS ablegen | G40: Geprüftes und im QMS abgelegtes Gruppenzertifikat | H40: jährlich | I40: 1 | J40: 15 | K40: 0.25 | L40: 30 | M40: 7.5 | N40: Verordnung (EU) 2018/848 | O40: Art. 36 Abs. 2 in Verbindung mit Art. 35 | P40: Das in Artikel 35 genannte Zertifikat wird für die gesamte Gruppe ausgestellt.
A41: BIO-0060 | B41: BioZBW | C41: Externer Lizenznehmer | D41: Lizenznahme der Erzeugergruppe / Zeichennutzerin | E41: Verträge | F41: Zeichennutzungsvertrag der Genossenschaft prüfen und gegenzeichnen sowie Programmanmeldung weiterleiten | G41: Gegengezeichneter Zeichennutzungsvertrag und programmgemäß registrierte Genossenschaft | H41: einmalig | I41: 1 | J41: 60 | K41: 1 | L41: 30 | M41: 30 | N41: BioZBW – Programmbestimmungen, Stand 01.01.2026 | O41: S. 22, Abschnitt 9.2 | P41: Die Teilnahme als Zeichennutzer ist nur auf der Grundlage eines Zeichennutzungsvertrages mit einem Lizenznehmer möglich.
A42: BIO-0061 | B42: BioZBW | C42: Genossenschaft / zentrale Einrichtung / Zeichennutzer | D42: Administrative Tätigkeiten als Zeichennutzer | E42: Datenaufzeichnung und -pflege | F42: BioZBW-Produktaufstellung aktualisieren und für Kontrollen bereitstellen | G42: Stets aktuelle Aufstellung der mit BioZBW gekennzeichneten und vermarkteten Produkte | H42: jährlich sowie bei Änderungen | I42: 1 | J42: 30 | K42: 0.5 | L42: 30 | M42: 15 | N42: BioZBW – Programmbestimmungen, Stand 01.01.2026 | O42: S. 27, Abschnitt 11.3 | P42: Zeichennutzer sind verpflichtet, eine stets aktuelle Aufstellung der Produkte vorzuhalten, die mit dem Biozeichen Baden-Württemberg gekennzeichnet und vermarktet werden.
A43: BIO-0062 | B43: BioZBW | C43: Genossenschaft / zentrale Einrichtung / Zeichennutzer | D43: Administrative Tätigkeiten als Zeichennutzer | E43: Archivierung von Nachweisen | F43: Qualitätsprüfung administrativ anmelden sowie Ergebnisnachweis zuordnen und bereithalten | G43: Aktueller Qualitätsprüfungsnachweis für BioZBW-Verarbeitungsprodukte | H43: gemäß Zertifikatslaufzeit; im Modell jährlich | I43: 1 | J43: 30 | K43: 0.5 | L43: 30 | M43: 15 | N43: BioZBW – Programmbestimmungen, Stand 01.01.2026; BioZBW – Zusatzanforderungen für pflanzliche Produkte, Stand 2024 | O43: Programmbestimmungen 2026, S. 15–16, Abschnitte 6.4–6.4.1; ZA pflanzliche Produkte 2024, S. 8–9, Abschnitt III.5 | P43: Verarbeitungsprodukte, für die eine Zeichennutzung erfolgt, müssen regelmäßig zu Qualitätsprüfungen angestellt werden. […] Der Qualitätsnachweis erfolgt durch regelmäßige Teilnahme an den Prüfungen der DLG oder an vergleichbaren Qualitätsprüfungen.
A44: BIO-0063 | B44: BioZBW | C44: Externer Lizenznehmer | D44: Laufende teilnehmerbezogene Lizenznehmerverwaltung | E44: Jährliche Teilnehmermeldung | F44: Jahresmeldung der angeschlossenen Erzeuger und Zeichennutzer erstellen, plausibilisieren und an die MBW übermitteln | G44: Jährliche zusammenfassende, nach Produktbereichen getrennte Meldung der angeschlossenen Erzeuger und Zeichennutzer an die MBW | H44: jährlich; teilnehmerbezogen | I44: =1 -> 1 | J44: =Annahmen!$C$91 -> 5 | K44: =I44*J44/60 -> 0.083333333 | L44: 30 | M44: =K44*L44 -> 2.5 | N44: BioZBW – Programmbestimmungen, Stand 01.01.2026 | O44: S. 27–28, Abschnitt 11.4; Zeitansatz siehe ANN-054 | P44: Lizenznehmer sind verpflichtet, jährlich zum 31. Dezember eine zusammenfassende Meldung über die angeschlossenen Erzeuger und Zeichennutzer bei der MBW […] abzugeben.
A45: BIO-0064 | B45: BioZBW | C45: Traubenerzeuger / landwirtschaftlicher Betrieb | D45: Traubenerzeuger; Bezugsform: Gruppe | E45: Ausfüllen von Checklisten und Formulare | F45: Eigenkontrollcheckliste des landwirtschaftlichen Betriebs ausfüllen und ablegen | G45: Vollständig ausgefüllte BioZBW-Eigenkontrollcheckliste des landwirtschaftlichen Betriebs | H45: jährlich (fachlich gesetzte Modellannahme) | I45: 1 | J45: 30 | K45: 0.5 | L45: 50 | M45: 25 | N45: Fachlich gesetzte Modellannahme der Studienleitung; nicht als eigenständige Pflicht in den ausgewerteten BioZBW-Dokumenten belegt | O45: Modellannahme vom 05.08.2026 | P45: Kein wörtliches Quellenzitat; die Pflicht zur Eigenkontrollcheckliste des Traubenerzeugers wurde für die Kostenmodellierung fachlich gesetzt.
A46: BIO-0065 | B46: BioZBW | C46: Kontroll-/Zertifizierungsstelle | D46: Externe Kontrolle; Bezugsform: Zeichennutzer | E46: Kontrollvorbereitung | F46: Jährliche Zeichennutzerkontrolle terminieren und programmspezifische Unterlagen anfordern | G46: Abgestimmter Termin und vollständiges Kontrollpaket der Genossenschaft als Zeichennutzerin | H46: jährlich; gruppenfix, anteilig je Mitglied (n=150) | I46: =1/Annahmen!$C$77 -> 0.0066666667 | J46: 15 | K46: =I46*J46/60 -> 0.0016666667 | L46: 30 | M46: =K46*L46 -> 0.05 | N46: BioZBW – Programmbestimmungen, Stand 01.01.2026 | O46: S. 17, Abschnitt 6.8; S. 27, Abschnitt 11.3; Zeitansatz siehe ANN-046 | P46: Erfassung, Handel, Verarbeitung (Zeichennutzer): 100 %.
A47: BIO-0066 | B47: BioZBW | C47: Kontroll-/Zertifizierungsstelle | D47: Externe Kontrolle; Bezugsform: Zeichennutzer | E47: Dokumentenprüfung und Kontrolldokumentation | F47: Eigenkontrollsystem, Produkt- und Qualitätsnachweise, Waren- und Herkunftsdokumentation, Rückverfolgbarkeit und Kennzeichnung prüfen und Kontrollcheckliste vervollständigen | G47: Dokumentierte jährliche Zeichennutzerkontrolle mit bewerteten Prüfpunkten und nachvollziehbarem Ergebnis | H47: jährlich; gruppenfix, anteilig je Mitglied (n=150) | I47: =1/Annahmen!$C$77 -> 0.0066666667 | J47: 60 | K47: =I47*J47/60 -> 0.0066666667 | L47: 30 | M47: =K47*L47 -> 0.2 | N47: BioZBW – Programmbestimmungen, Stand 01.01.2026; BioZBW-Kombicheckliste 2025 | O47: Programmbestimmungen S. 14–15, Abschnitt 6.2.1; Kombicheckliste S. 2–6; Zeitansatz siehe ANN-047 | P47: Kontrolle/Überprüfung des Eigenkontrollsystems bzw. der Dokumentationen.
A48: BIO-0067 | B48: BioZBW | C48: Kontroll-/Zertifizierungsstelle | D48: Externe Kontrolle; Bezugsform: Mitgliederstichprobe | E48: Stichprobenplanung | F48: Risikobasierte Mitgliederstichprobe auswählen und jährlichen Kontrollplan dokumentieren | G48: Nachvollziehbar ausgewählte Stichprobe von 15 Mitgliedern und dokumentierter Kontrollplan | H48: jährlich; gruppenfix, anteilig je Mitglied (n=150) | I48: =1/Annahmen!$C$77 -> 0.0066666667 | J48: 30 | K48: =I48*J48/60 -> 0.0033333333 | L48: 30 | M48: =K48*L48 -> 0.1 | N48: BioZBW – Programmbestimmungen, Stand 01.01.2026 | O48: S. 17, Abschnitt 6.8; Zeitansatz siehe ANN-043 | P48: Landwirtschaftliche Erzeuger pflanzlicher Produkte: mindestens 10 % jährlich.
A49: BIO-0068 | B49: BioZBW | C49: Kontroll-/Zertifizierungsstelle | D49: Externe Kontrolle; Bezugsform: Mitgliederstichprobe | E49: Administrative Kontrollvorbereitung | F49: Termin und Unterlagen je ausgewähltem Mitglied koordinieren und Kontrollakte vorbereiten | G49: Vorbereitete Kontrollakten für 15 programmspezifische Mitgliederkontrollen | H49: jährlich; 15 Stichproben je Gruppe, anteilig je Mitglied (n=150) | I49: =Annahmen!$C$79/Annahmen!$C$77 -> 0.1 | J49: 15 | K49: =I49*J49/60 -> 0.025 | L49: 30 | M49: =K49*L49 -> 0.75 | N49: BioZBW – Programmbestimmungen, Stand 01.01.2026 | O49: S. 17, Abschnitt 6.8; Zeitansatz siehe ANN-044 | P49: Landwirtschaftliche Erzeuger pflanzlicher Produkte: mindestens 10 % jährlich.
A50: BIO-0069 | B50: BioZBW | C50: Kontroll-/Zertifizierungsstelle | D50: Externe Kontrolle; Bezugsform: Mitgliederstichprobe | E50: Administrative Kontrollnachbereitung | F50: Kontrollcheckliste je Stichprobenmitglied abschließen, Ergebnis und gegebenenfalls Abweichungen dokumentieren und Kontrollakte schließen | G50: Vollständige administrative Abschlussdokumentation für 15 programmspezifische Mitgliederkontrollen | H50: jährlich; 15 Stichproben je Gruppe, anteilig je Mitglied (n=150) | I50: =Annahmen!$C$79/Annahmen!$C$77 -> 0.1 | J50: 15 | K50: =I50*J50/60 -> 0.025 | L50: 30 | M50: =K50*L50 -> 0.75 | N50: BioZBW – Programmbestimmungen, Stand 01.01.2026 | O50: S. 17 und 28, Abschnitte 6.8 und 11.5; Zeitansatz siehe ANN-045 | P50: Landwirtschaftliche Erzeuger pflanzlicher Produkte: mindestens 10 % jährlich.
A51: BIO-0070 | B51: BioZBW | C51: Externer Lizenznehmer | D51: Laufende teilnehmerbezogene Lizenznehmerverwaltung | E51: Programm- und Vertragsüberwachung | F51: Programminhalte und vertragliche Verpflichtungen der angeschlossenen Teilnehmer laufend überwachen | G51: Nachvollziehbar überwachter Teilnehmerstatus und dokumentierte Einhaltung der programmspezifischen und vertraglichen Pflichten | H51: jährlich; teilnehmerbezogen | I51: =1 -> 1 | J51: =Annahmen!$C$87 -> 10 | K51: =I51*J51/60 -> 0.16666667 | L51: 30 | M51: =K51*L51 -> 5 | N51: BioZBW – Programmbestimmungen, Stand 01.01.2026 | O51: S. 7–8, Abschnitt 3.2; Zeitansatz siehe ANN-050 | P51: Sie gewährleisten die ordnungsgemäße Umsetzung und Überwachung der Programminhalte bei den ihnen vertraglich angeschlossenen Erzeugern und Zeichennutzern.
...

Sheet Kostenrechnung
A1: Kostenrechnung – enge zertifizierungsspezifische Szenarien
A2: Aktuell sind ausschließlich QZBW und BioZBW ohne fachrechtliche/betriebliche Basisadministration. Alle Ergebnisse greifen formelbasiert auf die beiden Anforderungsblätter zu.
A4: Kennzahl | B4: QZBW (EUR) | C4: BioZBW (EUR) | D4: Differenz QZBW – BioZBW (EUR)
A5: Gesamtkosten eng | B5: =SUM(Anford_QZBW_zert_spez!$M$2:$M$55) -> 1099.7 | C5: =SUM(Anford_BioZBW_zert_spez!$M$2:$M$55) -> 1049.9 | D5: =B5-C5 -> 49.8
A6: Gesamtzeit eng (Std.) | B6: =SUM(Anford_QZBW_zert_spez!$K$2:$K$55) -> 34.24 | C6: =SUM(Anford_BioZBW_zert_spez!$K$2:$K$55) -> 33.246667 | D6: =B6-C6 -> 0.99333333
A7: Anzahl enthaltener Tätigkeiten | B7: =COUNT(Anford_QZBW_zert_spez!$M$2:$M$55) -> 53 | C7: =COUNT(Anford_BioZBW_zert_spez!$M$2:$M$55) -> 53 | D7: =B7-C7 -> 0
A9: Abstimmung | B9: Aktuelle Arbeitsversion (EUR) | C9: Interne V3 vor Abgrenzung (EUR) | D9: Methodische Veränderung (EUR) | E9: Status
A10: QZBW eng | B10: =B5 -> 1099.7 | C10: 1693.75 | D10: =B10-C10 -> -594.05 | E10: INFO – methodisch bereinigt
A11: BioZBW eng | B11: =C5 -> 1049.9 | C11: 1358.75 | D11: =B11-C11 -> -308.85 | E11: INFO – methodisch bereinigt
A12: Differenz QZBW – BioZBW | B12: =B10-B11 -> 49.8 | C12: 335 | D12: =B12-C12 -> -285.2 | E12: INFO – methodisch bereinigt
A15: Akteursgruppe | B15: QZBW Kosten (EUR) | C15: BioZBW Kosten (EUR) | D15: Differenz (EUR) | E15: QZBW Zeit (Std.) | F15: BioZBW Zeit (Std.) | H15: Rollenaufteilung Genossenschaft
A16: Traubenerzeuger / landwirtschaftlicher Betrieb | B16: =SUMIFS(Anford_QZBW_zert_spez!$M$2:$M$55,Anford_QZBW_zert_spez!$C$2:$C$55,$A16) -> 137.5 | C16: =SUMIFS(Anford_BioZBW_zert_spez!$M$2:$M$55,Anford_BioZBW_zert_spez!$C$2:$C$55,$A16) -> 87.5 | D16: =B16-C16 -> 50 | E16: =SUMIFS(Anford_QZBW_zert_spez!$K$2:$K$55,Anford_QZBW_zert_spez!$C$2:$C$55,$A16) -> 2.75 | F16: =SUMIFS(Anford_BioZBW_zert_spez!$K$2:$K$55,Anford_BioZBW_zert_spez!$C$2:$C$55,$A16) -> 1.75 | H16: Rolle der Genossenschaft | I16: QZBW (EUR) | J16: BioZBW (EUR) | K16: Differenz (EUR)
